<?xml version='1.0'?>
<robot name="dd_robot">
<!-- motor controller-->
<gazebo>  
      <plugin name="differential_drive_controller" filename="libgazebo_ros_diff_drive.so">
      <alwaysOn>true</alwaysOn>
    <legacyMode>false</legacyMode>
      <updateRate>10</updateRate>      
      <leftJoint>joint_left_wheel</leftJoint>     
      <rightJoint>joint_right_wheel</rightJoint>      
      <wheelSeparation>0.5</wheelSeparation>      
      <wheelDiameter>0.4</wheelDiameter>      
      <torque>2</torque>      
       <commandTopic>/cmd_vel</commandTopic>
      <odometryTopic>odom</odometryTopic>
      <odometryFrame>odom</odometryFrame>
      <robotBaseFrame>base_link</robotBaseFrame>
  </plugin>
</gazebo>  


  <!-- Base Link -->
  <link name="base_link">
    <visual>
      <origin xyz="0 0 0" rpy="0 0 0" />
      <geometry>
          <box size="0.3 0.2 0.1"/>
      </geometry>
      <material name="red">
        <color rgba="1 0 0 1"/>
      </material>
    </visual>
    <!-- Base collision, mass and inertia -->
    <collision>
      <origin xyz="0 0 0" rpy="0 0 0" />
      <geometry>
          <box size="0.3 0.2 0.1"/>
      </geometry>
    </collision>
    <inertial>
      <mass value="5"/>
      <!-- <inertia ixx="0.13" ixy="0.0" ixz="0.0" iyy="0.21" iyz="0.0" izz="0.13"/> -->
      <inertia ixx="0.041666667" ixy="0.0" ixz="0.0" iyy="0.041666667" iyz="0.0" izz="0.054166667"/>

    </inertial>

   
  </link>

<gazebo reference="base_link">
    <material>Gazebo/Blue</material>
    <pose>0 0 3 0 0 0</pose>
  </gazebo> 

<!-- Caster -->
  <link name="caster">
    <visual name="caster">
      <origin xyz="0 0 0" rpy="0 0 0" />
      <geometry>
        <sphere radius="0.025" />
      </geometry>
      <material name="red">
        <color rgba="1 0 0 1"/>
      </material>
    </visual>
    <!-- Caster collision, mass and inertia -->
    <collision>
      <!-- <origin xyz="0.12 0 -0.075" rpy="0 0 0" /> -->
      <origin xyz="0 0 0" rpy="0 0 0" />
      <geometry>
        <sphere radius="0.025" />
      </geometry>
    </collision>
    <inertial>
      <mass value="0.5"/>
      <!-- <inertia ixx="0.0001" ixy="0.0" ixz="0.0" iyy="0.0001" iyz="0.0" izz="0.0001"/> -->
      <inertia ixx="0.000125" ixy="0.0" ixz="0.0" iyy="0.000125" iyz="0.0" izz="0.000125"/>
    </inertial>
    </link>

<!-- caster joint -->
  <joint name="caster_joint" type="fixed">
    <parent link="base_link"/>
    <child link="caster"/>
    <origin xyz="0.12 0 -0.045" rpy="0 0 0" /> 
    <axis xyz="0 00 0" />
  </joint>
 
 

<gazebo reference="caster">
    <material>Gazebo/Red</material>
    <pose>0 0 3 0 0 0</pose>
    <mu1 value="0.001"/>
        <mu2 value="0.001"/>
  </gazebo>

 <gazebo reference="base_link">
    <material>Gazebo/Blue</material>
    <pose>0 0 3 0 0 0</pose>
  </gazebo>

  <!-- Right Wheel -->
  <link name="right_wheel">
    <visual>
      <origin xyz="0 0 0" rpy=" 1.570795 0 0" />
      <geometry>
          <cylinder length="0.01" radius="0.045" />
      </geometry>
      <material name="darkgray">
        <color rgba=".2 .2 .2 1"/>
      </material>
    </visual>
    <!-- Right Wheel collision, mass and inertia -->
    <collision>
      <origin xyz="0 0 0" rpy="1.570795 0 0" />
      <geometry>
          <cylinder length="0.01" radius="0.045" />
      </geometry>
    </collision>
    <inertial>
      <mass value="0.5"/>
      <!-- <inertia ixx="0.01" ixy="0.0" ixz="0.0" iyy="0.005" iyz="0.0" izz="0.005"/> -->
      <inertia ixx="0.000257292" ixy="0.0" ixz="0.0" iyy="0.000084375" iyz="0.0" izz="0.00050625"/>

    </inertial>

  </link>
<gazebo reference="right_wheel">
    <material>Gazebo/Black</material>
  </gazebo>

  <!-- Right Wheel joint -->
  <joint name="joint_right_wheel" type="continuous">
    <parent link="base_link"/>
    <child link="right_wheel"/>
    <origin xyz="-0.075 -0.11 -0.025" rpy="0 0 0" /> 
    <axis xyz="0 1 0" />
  </joint>

  <!-- Left Wheel -->
  <link name="left_wheel">
    <visual>
      <origin xyz="0 0 0" rpy="1.570795 0 0" />
      <geometry>
          <cylinder length="0.01" radius="0.045" />
      </geometry>
      <material name="darkgray">
        <color rgba=".2 .2 .2 1"/>
      </material>
    </visual>
    <!-- Left Wheel collision, mass and inertia -->
    <collision>
      <origin xyz="0 0 0" rpy="1.570795 0 0" />
      <geometry>
          <cylinder length="0.01" radius="0.045" />
      </geometry>
    </collision>
    <inertial>
      <mass value="0.5"/>
      <!-- <inertia ixx="0.01" ixy="0.0" ixz="0.0" iyy="0.005" iyz="0.0" izz="0.005"/> -->
      <inertia ixx="0.000257292" ixy="0.0" ixz="0.0" iyy="0.000084375" iyz="0.0" izz="0.00050625"/>

    </inertial>
  </link>
  
 <gazebo reference="left_wheel">
    <material>Gazebo/Black</material>
  </gazebo>
  <!-- Left Wheel joint -->
  <joint name="joint_left_wheel" type="continuous">
    <parent link="base_link"/>
    <child link="left_wheel"/>
    <origin xyz="-0.075 0.11 -0.025" rpy="0 0 0" /> 
    <axis xyz="0 1 0" />
  </joint>

</robot>